Workbook

Sheet Entrega
N1: A | O1: B | S1: Sergio
A2: Colegio | B2: rbd | C2: section_ | D2: Region | E2: Encuestador | F2: Fecha Entrega Focus | G2: Curso | H2: Letra | I2: Archivos Digitales | J2: total | K2: digitalizadas | L2: diferencia | M2: obs dif | N2: Forma A | O2: Forma B | P2: Estado | Q2: Diferencias | R2: Digitadas BD | S2: Forma A 2 | T2: Forma B 2 | U2: Blanco | V2: Digitalizada
A3: Colegio San Martín | B3: =vlookup(A3,rbds!A:B,2) -> 2220 | C3: =B3&"-"&G3&"-"&H3 -> 2220-7-a | D3: Ohiggins | E3: Paola | F3: 45849 | G3: 7 | H3: a | I3: 29 | J3: =N3+O3 -> 29 | K3: =VLOOKUP(C3,'6_7_count'!F:G,2) -> 29 | L3: =J3-K3 -> 0 | N3: 13 | O3: 16 | S3: 13 | T3: 16 | U3: 2 ausentes 4 retirados | V3: 1 | AC3: =SEARCHB(C3,'4_5_count'!F:G,1) -> #VALUE!
A4: Colegio San Martín | B4: =vlookup(A4,rbds!A:B,2) -> 2220 | C4: =B4&"-"&G4&"-"&H4 -> 2220-6-a | D4: Ohiggins | E4: Paola | F4: 45849 | G4: 6 | H4: a | I4: 28 | J4: =N4+O4 -> 28 | K4: =VLOOKUP(C4,'6_7_count'!F:G,2) -> 28 | L4: =J4-K4 -> 0 | N4: 9 | O4: 19 | S4: 9 | T4: 19 | U4: 2 ausentes 3 retirados | V4: 1
A5: Colegio San Martín | B5: =vlookup(A5,rbds!A:B,2) -> 2220 | C5: =B5&"-"&G5&"-"&H5 -> 2220-5-a | D5: Ohiggins | E5: Paola | F5: 45849 | G5: 5 | H5: a | I5: 38 | J5: =N5+O5 -> 38 | K5: =VLOOKUP(C5,'4_5_count'!F:G,2) -> 38 | L5: =J5-K5 -> 0 | N5: 19 | O5: 19 | S5: 19 | T5: 19 | U5: 1 ausente | V5: 1
A6: Colegio San Martín | B6: =vlookup(A6,rbds!A:B,2) -> 2220 | C6: =B6&"-"&G6&"-"&H6 -> 2220-4-a | D6: Ohiggins | E6: Paola | F6: 45849 | G6: 4 | H6: a | I6: 35 | J6: =N6+O6 -> 35 | K6: =VLOOKUP(C6,'4_5_count'!F:G,2) -> 35 | L6: =J6-K6 -> 0 | N6: 17 | O6: 18 | S6: 17 | T6: 18 | U6: 3 ausentes 3 retirados | V6: 1
A7: Esc. Adriana Aranguiz Cerda | B7: =vlookup(A7,rbds!A:B,2) -> 11248 | C7: =B7&"-"&G7&"-"&H7 -> 11248-4-a | D7: Ohiggins | E7: Paola | F7: 45849 | G7: 4 | H7: a | I7: 24 | J7: =N7+O7 -> 24 | K7: =VLOOKUP(C7,'4_5_count'!F:G,2) -> 24 | L7: =J7-K7 -> 0 | N7: 10 | O7: 14 | S7: 10 | T7: 14 | U7: 1 retirado
A8: Esc. Adriana Aranguiz Cerda | B8: =vlookup(A8,rbds!A:B,2) -> 11248 | C8: =B8&"-"&G8&"-"&H8 -> 11248-5-a | D8: Ohiggins | E8: Paola | F8: 45849 | G8: 5 | H8: a | I8: 21 | J8: =N8+O8 -> 21 | K8: =VLOOKUP(C8,'4_5_count'!F:G,2) -> 21 | L8: =J8-K8 -> 0 | N8: 8 | O8: 13 | S8: 8 | T8: 13 | U8: 3 ausentes 1 retirado
A9: Esc. Adriana Aranguiz Cerda | B9: =vlookup(A9,rbds!A:B,2) -> 11248 | C9: =B9&"-"&G9&"-"&H9 -> 11248-6-a | D9: Ohiggins | E9: Paola | F9: 45849 | G9: 6 | H9: a | I9: 18 | J9: =N9+O9 -> 18 | K9: =VLOOKUP(C9,'6_7_count'!F:G,2) -> 18 | L9: =J9-K9 -> 0 | N9: 8 | O9: 10 | S9: 8 | T9: 10 | U9: 4 ausentes
A10: Esc. Adriana Aranguiz Cerda | B10: =vlookup(A10,rbds!A:B,2) -> 11248 | C10: =B10&"-"&G10&"-"&H10 -> 11248-7-a | D10: Ohiggins | E10: Paola | F10: 45849 | G10: 7 | H10: a | I10: 35 | J10: =N10+O10 -> 35 | K10: =VLOOKUP(C10,'6_7_count'!F:G,2) -> 35 | L10: =J10-K10 -> 0 | N10: 18 | O10: 17 | S10: 18 | T10: 17 | U10: 1 retirado
A11: Colegio Particular Whipple School | B11: =vlookup(A11,rbds!A:B,2) -> 2155 | C11: =B11&"-"&G11&"-"&H11 -> 2155-7-a | D11: Ohiggins | E11: Paola | F11: 45849 | G11: 7 | H11: a | I11: 22 | J11: =N11+O11 -> 22 | K11: =VLOOKUP(C11,'6_7_count'!F:G,2) -> 22 | L11: =J11-K11 -> 0 | N11: 9 | O11: 13 | S11: 9 | T11: 13 | U11: 3 ausentes | V11: 1
A12: Colegio Particular Whipple School | B12: =vlookup(A12,rbds!A:B,2) -> 2155 | C12: =B12&"-"&G12&"-"&H12 -> 2155-7-b | D12: Ohiggins | E12: Paola | F12: 45849 | G12: 7 | H12: b | I12: 25 | J12: =N12+O12 -> 26 | K12: =VLOOKUP(C12,'6_7_count'!F:G,2) -> 24 | L12: =J12-K12 -> 2 | M12: venía 2 menos | N12: 13 | O12: 13 | S12: 13 | T12: 13 | U12: 1 ausente | V12: 1
A13: Colegio Particular Whipple School | B13: =vlookup(A13,rbds!A:B,2) -> 2155 | C13: =B13&"-"&G13&"-"&H13 -> 2155-6-a | D13: Ohiggins | E13: Paola | F13: 45849 | G13: 6 | H13: a | I13: 24 | J13: =N13+O13 -> 24 | K13: =VLOOKUP(C13,'6_7_count'!F:G,2) -> 24 | L13: =J13-K13 -> 0 | N13: 13 | O13: 11 | S13: 13 | T13: 11 | U13: 2 ausentes 1 retirado | V13: 1
A14: Colegio Particular Whipple School | B14: =vlookup(A14,rbds!A:B,2) -> 2155 | C14: =B14&"-"&G14&"-"&H14 -> 2155-6-b | D14: Ohiggins | E14: Paola | F14: 45849 | G14: 6 | H14: b | I14: 20 | J14: =N14+O14 -> 20 | K14: =VLOOKUP(C14,'6_7_count'!F:G,2) -> 20 | L14: =J14-K14 -> 0 | N14: 9 | O14: 11 | S14: 9 | T14: 11 | U14: 1 ausente 2 retirados | V14: 1
A15: Colegio Particular Whipple School | B15: =vlookup(A15,rbds!A:B,2) -> 2155 | C15: =B15&"-"&G15&"-"&H15 -> 2155-5-a | D15: Ohiggins | E15: Paola | F15: 45849 | G15: 5 | H15: a | I15: 40 | J15: =N15+O15 -> 40 | K15: =VLOOKUP(C15,'4_5_count'!F:G,2) -> 39 | L15: =I15-K15 -> 1 | M15: venían 1 menos | N15: 26 | O15: 14 | S15: 25 | T15: 14 | U15: 1 ausente 4 retirados 1 blanco | V15: 1
A16: Colegio Particular Whipple School | B16: =vlookup(A16,rbds!A:B,2) -> 2155 | C16: =B16&"-"&G16&"-"&H16 -> 2155-4-a | D16: Ohiggins | E16: Paola | F16: 45849 | G16: 4 | H16: a | I16: 35 | J16: =N16+O16 -> 35 | K16: =VLOOKUP(C16,'4_5_count'!F:G,2) -> 35 | L16: =J16-K16 -> 0 | N16: 18 | O16: 17 | S16: 18 | T16: 17 | U16: 4 ausentes 1 retirado | V16: 1
A17: Colegio Whipple School Oriente | B17: =vlookup(A17,rbds!A:B,2) -> 40038 | C17: =B17&"-"&G17&"-"&H17 -> 40038-4-a | D17: Ohiggins | E17: Jaime | F17: 45849 | G17: 4 | H17: a | I17: 25 | J17: =N17+O17 -> 25 | K17: =VLOOKUP(C17,'4_5_count'!F:G,2) -> 25 | L17: =J17-K17 -> 0 | N17: 12 | O17: 13 | S17: 12 | T17: 13 | U17: 1 retirado | V17: 1
A18: Colegio Whipple School Oriente | B18: =vlookup(A18,rbds!A:B,2) -> 40038 | C18: =B18&"-"&G18&"-"&H18 -> 40038-7-b | D18: Ohiggins | E18: Jaime | F18: 45849 | G18: 7 | H18: b | I18: 21 | J18: =N18+O18 -> 21 | K18: =VLOOKUP(C18,'6_7_count'!F:G,2) -> 21 | L18: =J18-K18 -> 0 | N18: 12 | O18: 9 | S18: 12 | T18: 9 | U18: 2 ausentes | V18: 1
A19: Colegio Whipple School Oriente | B19: =vlookup(A19,rbds!A:B,2) -> 40038 | C19: =B19&"-"&G19&"-"&H19 -> 40038-4-b | D19: Ohiggins | E19: Jaime | F19: 45849 | G19: 4 | H19: b | I19: 26 | J19: =N19+O19 -> 26 | K19: =VLOOKUP(C19,'4_5_count'!F:G,2) -> 26 | L19: =J19-K19 -> 0 | N19: 13 | O19: 13 | S19: 13 | T19: 13 | U19: 2 ausentes | V19: 1
A20: Colegio Whipple School Oriente | B20: =vlookup(A20,rbds!A:B,2) -> 40038 | C20: =B20&"-"&G20&"-"&H20 -> 40038-6-a | D20: Ohiggins | E20: Jaime | F20: 45849 | G20: 6 | H20: a | I20: 21 | J20: =N20+O20 -> 21 | K20: =VLOOKUP(C20,'6_7_count'!F:G,2) -> 21 | L20: =J20-K20 -> 0 | N20: 11 | O20: 10 | S20: 11 | T20: 10 | U20: 8 blancos | V20: 1
A21: Colegio Whipple School Oriente | B21: =vlookup(A21,rbds!A:B,2) -> 40038 | C21: =B21&"-"&G21&"-"&H21 -> 40038-5-b | D21: Ohiggins | E21: Jaime | F21: 45849 | G21: 5 | H21: b | I21: 26 | J21: =N21+O21 -> 26 | K21: =VLOOKUP(C21,'4_5_count'!F:G,2) -> 26 | L21: =J21-K21 -> 0 | N21: 17 | O21: 9 | S21: 17 | T21: 9 | U21: 1 ausente | V21: 1
A22: Colegio Whipple School Oriente | B22: =vlookup(A22,rbds!A:B,2) -> 40038 | C22: =B22&"-"&G22&"-"&H22 -> 40038-5-a | D22: Ohiggins | E22: Jaime | F22: 45849 | G22: 5 | H22: a | I22: 23 | J22: =N22+O22 -> 23 | K22: =VLOOKUP(C22,'4_5_count'!F:G,2) -> 23 | L22: =J22-K22 -> 0 | N22: 13 | O22: 10 | S22: 13 | T22: 10 | U22: 3 retirados | V22: 1
A23: Colegio Whipple School Oriente | B23: =vlookup(A23,rbds!A:B,2) -> 40038 | C23: =B23&"-"&G23&"-"&H23 -> 40038-7-a | D23: Ohiggins | E23: Jaime | F23: 45849 | G23: 7 | H23: a | I23: 18 | J23: =N23+O23 -> 18 | K23: =VLOOKUP(C23,'6_7_count'!F:G,2) -> 18 | L23: =J23-K23 -> 0 | N23: 8 | O23: 10 | S23: 8 | T23: 10 | U23: 3 blancos | V23: 1
A24: Colegio San Manuel | B24: =vlookup(A24,rbds!A:B,2) -> 24675 | C24: =B24&"-"&G24&"-"&H24 -> 24675-7-a | D24: RM | E24: Jesús | F24: 45849 | G24: 7 | H24: a | I24: 34 | J24: =N24+O24 -> 35 | K24: =VLOOKUP(C24,'6_7_count'!F:G,2) -> 34 | L24: =J24-K24 -> 1 | M24: venía 1 menos | N24: 17 | O24: 18 | S24: 16 | T24: 18 | U24: 2 blancos 1 ausente | V24: 1
A25: Colegio San Manuel | B25: =vlookup(A25,rbds!A:B,2) -> 24675 | C25: =B25&"-"&G25&"-"&H25 -> 24675-6-a | D25: RM | E25: Jesús | F25: 45849 | G25: 6 | H25: a | I25: 36 | J25: =N25+O25 -> 36 | K25: =VLOOKUP(C25,'6_7_count'!F:G,2) -> 36 | L25: =J25-K25 -> 0 | N25: 17 | O25: 19 | S25: 17 | T25: 19 | U25: 1 ausente | V25: 1
A26: Colegio San Manuel | B26: =vlookup(A26,rbds!A:B,2) -> 24675 | C26: =B26&"-"&G26&"-"&H26 -> 24675-5-a | D26: RM | E26: Jesús | F26: 45849 | G26: 5 | H26: a | I26: 35 | J26: =N26+O26 -> 34 | K26: =VLOOKUP(C26,'4_5_count'!F:G,2) -> 35 | L26: =J26-K26 -> -1 | M26: venía 1 más | N26: 17 | O26: 17 | S26: 17 | T26: 17 | U26: 3 ausentes 1 blanco | V26: 1
A27: Colegio San Manuel | B27: =vlookup(A27,rbds!A:B,2) -> 24675 | C27: =B27&"-"&G27&"-"&H27 -> 24675-4-a | D27: RM | E27: Jesús | F27: 45849 | G27: 4 | H27: a | I27: 35 | J27: =N27+O27 -> 35 | K27: =VLOOKUP(C27,'4_5_count'!F:G,2) -> 35 | L27: =J27-K27 -> 0 | N27: 18 | O27: 17 | S27: 18 | T27: 17 | U27: 2 ausentes | V27: 1
A28: Escuela Básica g-n° 737 Santa Emilia | B28: =vlookup(A28,rbds!A:B,2) -> 10840 | C28: =B28&"-"&G28&"-"&H28 -> 10840-6-a | D28: RM | E28: Antonia | F28: 45849 | G28: 6 | H28: a | I28: 17 | J28: =N28+O28 -> 17 | K28: 17 | L28: =J28-K28 -> 0 | N28: 11 | O28: 6 | S28: 11 | T28: 6 | U28: 3 ausentes
A29: Escuela Básica g-n° 737 Santa Emilia | B29: =vlookup(A29,rbds!A:B,2) -> 10840 | C29: =B29&"-"&G29&"-"&H29 -> 10840-5-a | D29: RM | E29: Antonia | F29: 45849 | G29: 5 | H29: a | I29: 23 | J29: =N29+O29 -> 23 | K29: =VLOOKUP(C29,'4_5_count'!F:G,2) -> 23 | L29: =J29-K29 -> 0 | N29: 13 | O29: 10 | S29: 14 | T29: 9 | U29: 3 ausentes 1 retirado
A30: Escuela Básica g-n° 737 Santa Emilia | B30: =vlookup(A30,rbds!A:B,2) -> 10840 | C30: =B30&"-"&G30&"-"&H30 -> 10840-4-a | D30: RM | E30: Magdalena | F30: 45849 | G30: 4 | H30: a | I30: 28 | J30: =N30+O30 -> 29 | K30: =VLOOKUP(C30,'4_5_count'!F:G,2) -> 28 | L30: =J30-K30 -> 1 | M30: venía 1 menos | N30: 14 | O30: 15 | S30: 13 | T30: 15 | U30: 1 blanco 4 ausentes
A31: Escuela Básica g-n° 737 Santa Emilia | B31: =vlookup(A31,rbds!A:B,2) -> 10840 | C31: =B31&"-"&G31&"-"&H31 -> 10840-7-a | D31: RM | E31: Magdalena | F31: 45849 | G31: 7 | H31: a | I31: 27 | J31: =N31+O31 -> 27 | K31: 27 | L31: =J31-K31 -> 0 | N31: 11 | O31: 16 | S31: 11 | T31: 16 | U31: 4 retirados 5 ausentes
A32: Escuela Básica Particular Paicaví de Lampa | B32: =vlookup(A32,rbds!A:B,2) -> 26235 | C32: =B32&"-"&G32&"-"&H32 -> 26235-7-a | D32: RM | E32: Mónica | F32: 45849 | G32: 7 | H32: a | I32: 22 | J32: =N32+O32 -> 23 | K32: =VLOOKUP(C32,'6_7_count'!F:G,2) -> 22 | L32: =J32-K32 -> 1 | M32: venía 1 menos | N32: 13 | O32: 10 | S32: 13 | T32: 9 | U32: 1 retirado 5 ausentes 1 blanco
A33: Escuela Básica Particular Paicaví de Lampa | B33: =vlookup(A33,rbds!A:B,2) -> 26235 | C33: =B33&"-"&G33&"-"&H33 -> 26235-6-a | D33: RM | E33: Magdalena | F33: 45849 | G33: 6 | H33: a | I33: 21 | J33: =N33+O33 -> 21 | K33: =VLOOKUP(C33,'6_7_count'!F:G,2) -> 21 | L33: =J33-K33 -> 0 | N33: 13 | O33: 8 | S33: 13 | T33: 8
A34: Escuela Básica Particular Paicaví de Lampa | B34: =vlookup(A34,rbds!A:B,2) -> 26235 | C34: =B34&"-"&G34&"-"&H34 -> 26235-5-a | D34: RM | E34: Mónica | F34: 45849 | G34: 5 | H34: a | I34: 30 | J34: =N34+O34 -> 30 | K34: =VLOOKUP(C34,'4_5_count'!F:G,2) -> 30 | L34: =J34-K34 -> 0 | N34: 15 | O34: 15 | S34: 16 | T34: 14 | U34: 2 ausentes
A35: Escuela Básica Particular Paicaví de Lampa | B35: =vlookup(A35,rbds!A:B,2) -> 26235 | C35: =B35&"-"&G35&"-"&H35 -> 26235-4-a | D35: RM | E35: Magdalena | F35: 45849 | G35: 4 | H35: a | I35: 30 | J35: =N35+O35 -> 29 | K35: =VLOOKUP(C35,'4_5_count'!F:G,2) -> 29 | L35: =J35-K35 -> 0 | N35: 16 | O35: 13 | S35: 16 | T35: 13
A36: Escuela Premio Nobel Pablo Neruda | B36: =vlookup(A36,rbds!A:B,2) -> 10403 | C36: =B36&"-"&G36&"-"&H36 -> 10403-7-a | D36: RM | E36: Antonia | F36: 45849 | G36: 7 | H36: a | I36: 31 | J36: =N36+O36 -> 33 | K36: =VLOOKUP(C36,'6_7_count'!F:G,2) -> 30 | L36: =J36-K36 -> 3 | M36: venía 2 menos | N36: 23 | O36: 10 | S36: 21 | T36: 10 | U36: 3 blanco | V36: 1
A37: Escuela Premio Nobel Pablo Neruda | B37: =vlookup(A37,rbds!A:B,2) -> 10403 | C37: =B37&"-"&G37&"-"&H37 -> 10403-6-a | D37: RM | E37: Jesús | F37: 45849 | G37: 6 | H37: a | I37: 31 | J37: =N37+O37 -> 31 | K37: =VLOOKUP(C37,'6_7_count'!F:G,2) -> 31 | L37: =J37-K37 -> 0 | N37: 19 | O37: 12 | S37: 19 | T37: 12 | U37: 7 ausentes | V37: 1
A38: Escuela Premio Nobel Pablo Neruda | B38: =vlookup(A38,rbds!A:B,2) -> 10403 | C38: =B38&"-"&G38&"-"&H38 -> 10403-6-b | D38: RM | E38: Jesús | F38: 45849 | G38: 6 | H38: b | I38: 33 | J38: =N38+O38 -> 33 | K38: =VLOOKUP(C38,'6_7_count'!F:G,2) -> 33 | L38: =J38-K38 -> 0 | N38: 22 | O38: 11 | S38: 22 | T38: 11 | U38: 2 ausentes | V38: 1
A39: Escuela Premio Nobel Pablo Neruda | B39: =vlookup(A39,rbds!A:B,2) -> 10403 | C39: =B39&"-"&G39&"-"&H39 -> 10403-4-b | D39: RM | E39: Antonia | F39: 45849 | G39: 4 | H39: b | I39: 36 | J39: =N39+O39 -> 37 | K39: =VLOOKUP(C39,'4_5_count'!F:G,2) -> 36 | L39: =J39-K39 -> 1 | M39: venía 1 menos | N39: 21 | O39: 16 | S39: 21 | T39: 15 | U39: 1 ausente | V39: 1
A40: Escuela Premio Nobel Pablo Neruda | B40: =vlookup(A40,rbds!A:B,2) -> 10403 | C40: =B40&"-"&G40&"-"&H40 -> 10403-4-a | D40: RM | E40: Antonia | F40: 45849 | G40: 4 | H40: a | I40: 30 | J40: =N40+O40 -> 30 | K40: =VLOOKUP(C40,'4_5_count'!F:G,2) -> 30 | L40: =J40-K40 -> 0 | N40: 14 | O40: 16 | S40: 14 | T40: 16 | U40: 6 ausentes 1 blanco | V40: 1
...

Sheet revisar
A1: Ja | B1: curso | C1: letra | D1: nombre | E1: rut | F1: nom_est | G1: nombre | H1: rut | I1: sexo | J1: stata nom | K1: stata rut
A2: 21554A1 | B2: 4 | C2: A | D2: Luciano Quilodran | E2: - | F2: Colegio Particular Whipple School | G2: Luciano Quintero | H2: 24794073-1 | J2: ="replace nombre = """&G2&""" if folio == """&A2&"""" -> replace nombre = "Luciano Quintero" if folio == "21554A1" | K2: ="replace rut = """&H2&""" if folio == """&A2&"""" -> replace rut = "24794073-1" if folio == "21554A1"
A3: 21554A2 | B3: 4 | C3: A | D3: Emiliano Valentin Quiroz Gomez | E3: - | F3: Colegio Particular Whipple School | G3: Emiliano Valentin Quiroz Gómez | H3: 25104165-2 | J3: ="replace nombre = """&G3&""" if folio == """&A3&"""" -> replace nombre = "Emiliano Valentin Quiroz Gómez" if folio == "21554A2" | K3: ="replace rut = """&H3&""" if folio == """&A3&"""" -> replace rut = "25104165-2" if folio == "21554A2"
A4: 21554A3 | B4: 4 | C4: A | D4: Kaeylin Valdivia | E4: - | F4: Colegio Particular Whipple School | G4: Joaquin Valdivia | H4: 25289546-9 | J4: ="replace nombre = """&G4&""" if folio == """&A4&"""" -> replace nombre = "Joaquin Valdivia" if folio == "21554A3" | K4: ="replace rut = """&H4&""" if folio == """&A4&"""" -> replace rut = "25289546-9" if folio == "21554A3"
A5: 21554A4 | B5: 4 | C5: A | D5: Cyose Tarragoniez | E5: - | F5: Colegio Particular Whipple School | G5: José Parraguez | H5: 25054492-8 | J5: ="replace nombre = """&G5&""" if folio == """&A5&"""" -> replace nombre = "José Parraguez" if folio == "21554A4" | K5: ="replace rut = """&H5&""" if folio == """&A5&"""" -> replace rut = "25054492-8" if folio == "21554A4"
A6: 21555A1 | B6: 5 | C6: A | D6: Aeirys Noemy Cavieres Contreras | E6: - | F6: Colegio Particular Whipple School | G6: Aiirys Noemy Cavieres Contreras | H6: 24502267-0 | J6: ="replace nombre = """&G6&""" if folio == """&A6&"""" -> replace nombre = "Aiirys Noemy Cavieres Contreras" if folio == "21555A1" | K6: ="replace rut = """&H6&""" if folio == """&A6&"""" -> replace rut = "24502267-0" if folio == "21555A1"
A7: 21555A2 | B7: 5 | C7: A | D7: Sinon Neftali Burgos Piña | E7: - | F7: Colegio Particular Whipple School | G7: Simon Neftalí Burgos Piña | H7: 24937139-4 | J7: ="replace nombre = """&G7&""" if folio == """&A7&"""" -> replace nombre = "Simon Neftalí Burgos Piña" if folio == "21555A2" | K7: ="replace rut = """&H7&""" if folio == """&A7&"""" -> replace rut = "24937139-4" if folio == "21555A2"
A8: 21555A3 | B8: 5 | C8: A | D8: Cristopher Alexis Telles Telles | E8: - | F8: Colegio Particular Whipple School | G8: Cristopher Alexis Telles Telles | H8: 24546633-1 | J8: ="replace nombre = """&G8&""" if folio == """&A8&"""" -> replace nombre = "Cristopher Alexis Telles Telles" if folio == "21555A3" | K8: ="replace rut = """&H8&""" if folio == """&A8&"""" -> replace rut = "24546633-1" if folio == "21555A3"
A9: 21555A4 | B9: 5 | C9: A | D9: Thalma Antonella Sanchez Rodriguez | E9: - | F9: Colegio Particular Whipple School | G9: Noelia Antonella Sanchez Rodriguez | H9: 24247663-8 | J9: ="replace nombre = """&G9&""" if folio == """&A9&"""" -> replace nombre = "Noelia Antonella Sanchez Rodriguez" if folio == "21555A4" | K9: ="replace rut = """&H9&""" if folio == """&A9&"""" -> replace rut = "24247663-8" if folio == "21555A4"
A10: 21555A5 | B10: 5 | C10: A | D10: April Trinidad Díaz Tanayo | E10: - | F10: Colegio Particular Whipple School | G10: April Trinidad Díaz Tarayo | H10: 24926706-6 | J10: ="replace nombre = """&G10&""" if folio == """&A10&"""" -> replace nombre = "April Trinidad Díaz Tarayo" if folio == "21555A5" | K10: ="replace rut = """&H10&""" if folio == """&A10&"""" -> replace rut = "24926706-6" if folio == "21555A5"
A11: 21555A6 | B11: 5 | C11: A | D11: Maximiliano Isalan Marceliano Ignacio Salas Pizano | E11: - | F11: Colegio Particular Whipple School | G11: Maximiliano Ignacio Salas Pizarro | H11: 24762658-1 | J11: ="replace nombre = """&G11&""" if folio == """&A11&"""" -> replace nombre = "Maximiliano Ignacio Salas Pizarro" if folio == "21555A6" | K11: ="replace rut = """&H11&""" if folio == """&A11&"""" -> replace rut = "24762658-1" if folio == "21555A6"
A12: 21555A7 | B12: 5 | C12: A | D12: ALVARO NICOLAS RUIZ QUINTEROS | E12: - | F12: Colegio Particular Whipple School | G12: Álvaro Nicolas Ruiz Quinteros | H12: 24902219-5 | J12: ="replace nombre = """&G12&""" if folio == """&A12&"""" -> replace nombre = "Álvaro Nicolas Ruiz Quinteros" if folio == "21555A7" | K12: ="replace rut = """&H12&""" if folio == """&A12&"""" -> replace rut = "24902219-5" if folio == "21555A7"
A13: 22204A1 | B13: 4 | C13: A | D13: MELANY Blanco | E13: - | F13: Colegio San Martín | G13: Melany Blanco Mahani | H13: 100830776-4 | J13: ="replace nombre = """&G13&""" if folio == """&A13&"""" -> replace nombre = "Melany Blanco Mahani" if folio == "22204A1" | K13: ="replace rut = """&H13&""" if folio == """&A13&"""" -> replace rut = "100830776-4" if folio == "22204A1"
... A21: 22205A3 | B21: 5 | C21: A | D21: José manuel yuvaraz montenegre | E21: - | F21: Colegio San Martín | G21: José Manuel Guerrero Montenegro | H21: 24808129-5 | J21: ="replace nombre = """&G21&""" if folio == """&A21&"""" -> replace nombre = "José Manuel Guerrero Montenegro" if folio == "22205A3" | K21: ="replace rut = """&H21&""" if folio == """&A21&"""" -> replace rut = "24808129-5" if folio == "22205A3"
A22: 22205A4 | B22: 5 | C22: A | D22: LUCAS MATEO SIERPE LARA | E22: - | F22: Colegio San Martín | G22: Brianna Polette Ramirez Suarez | H22: 24411997-2 | I22: mujer | J22: ="replace nombre = """&G22&""" if folio == """&A22&"""" -> replace nombre = "Brianna Polette Ramirez Suarez" if folio == "22205A4" | K22: ="replace rut = """&H22&""" if folio == """&A22&"""" -> replace rut = "24411997-2" if folio == "22205A4"
A23: 22205A5 | B23: 5 | C23: A | D23: Omittomy masidimas Anthony Sadiel Hardones Hartinez | E23: - | F23: Colegio San Martín | G23: Anthony Jadiel Mardones Martinez | H23: 24703324-6 | J23: ="replace nombre = """&G23&""" if folio == """&A23&"""" -> replace nombre = "Anthony Jadiel Mardones Martinez" if folio == "22205A5" | K23: ="replace rut = """&H23&""" if folio == """&A23&"""" -> replace rut = "24703324-6" if folio == "22205A5"
A24: 22205A6 | B24: 5 | C24: A | D24: Viviana Gana | E24: - | F24: Colegio San Martín | G24: Viviana Antonella Gana Campos | H24: 24308007-k | J24: ="replace nombre = """&G24&""" if folio == """&A24&"""" -> replace nombre = "Viviana Antonella Gana Campos" if folio == "22205A6" | K24: ="replace rut = """&H24&""" if folio == """&A24&"""" -> replace rut = "24308007-k" if folio == "22205A6"
A25: 22205A7 | B25: 5 | C25: A | D25: NATHAN OLIVER SILVA MADRID | E25: - | F25: Colegio San Martín | G25: Nathian Oliver Silva Madrid | H25: 24228600-6 | J25: ="replace nombre = """&G25&""" if folio == """&A25&"""" -> replace nombre = "Nathian Oliver Silva Madrid" if folio == "22205A7" | K25: ="replace rut = """&H25&""" if folio == """&A25&"""" -> replace rut = "24228600-6" if folio == "22205A7"
A26: 22205A8 | B26: 5 | C26: A | D26: Amanda antonella García Cifuentes | E26: - | F26: Colegio San Martín | G26: Amanda Antonella Alejandra Cifuentes | H26: 24821701-4 | J26: ="replace nombre = """&G26&""" if folio == """&A26&"""" -> replace nombre = "Amanda Antonella Alejandra Cifuentes" if folio == "22205A8" | K26: ="replace rut = """&H26&""" if folio == """&A26&"""" -> replace rut = "24821701-4" if folio == "22205A8"
A27: 22205A9 | B27: 5 | C27: A | D27: DAFNE ANTONELLA ANABALÓN RODRÍGUEZ | E27: - | F27: Colegio San Martín | G27: Camila Martinez Blemonte | I27: mujer | J27: ="replace nombre = """&G27&""" if folio == """&A27&"""" -> replace nombre = "Camila Martinez Blemonte" if folio == "22205A9" | K27: ="replace rut = """&H27&""" if folio == """&A27&"""" -> replace rut = "" if folio == "22205A9"
A28: 23394A2 | B28: 4 | C28: A | D28: CHRISTOPER DANIEL DINAMARCA CATALAN | E28: - | F28: Escuela Municipal Zuniga | G28: Christopher Daniel Dinamarca Catalán | H28: 25065915-6 | J28: ="replace nombre = """&G28&""" if folio == """&A28&"""" -> replace nombre = "Christopher Daniel Dinamarca Catalán" if folio == "23394A2" | K28: ="replace rut = """&H28&""" if folio == """&A28&"""" -> replace rut = "25065915-6" if folio == "23394A2"
A29: 23394A3 | B29: 4 | C29: A | D29: Tarkowski Torres Inari Antonio | E29: - | F29: Escuela Municipal Zuniga | G29: Inari Tarkowski Torres | H29: 25072735-6 | J29: ="replace nombre = """&G29&""" if folio == """&A29&"""" -> replace nombre = "Inari Tarkowski Torres" if folio == "23394A3" | K29: ="replace rut = """&H29&""" if folio == """&A29&"""" -> replace rut = "25072735-6" if folio == "23394A3"
A30: 23394A4 | B30: 4 | C30: A | D30: Maily Barba Peres | E30: - | F30: Escuela Municipal Zuniga | G30: Maily Barba Perez | H30: 100836932-8 | J30: ="replace nombre = """&G30&""" if folio == """&A30&"""" -> replace nombre = "Maily Barba Perez" if folio == "23394A4" | K30: ="replace rut = """&H30&""" if folio == """&A30&"""" -> replace rut = "100836932-8" if folio == "23394A4"
A31: 23395A2 | B31: 5 | C31: A | D31: ANTONELLA RAQUEL TORO CEBALLOS | E31: - | F31: Escuela Municipal Zuniga | G31: ANTONELLA RAQUEL TORO CEBALLOS | H31: 24882844-7 | J31: ="replace nombre = """&G31&""" if folio == """&A31&"""" -> replace nombre = "ANTONELLA RAQUEL TORO CEBALLOS" if folio == "23395A2" | K31: ="replace rut = """&H31&""" if folio == """&A31&"""" -> replace rut = "24882844-7" if folio == "23395A2"
A32: 23395A3 | B32: 5 | C32: A | D32: Francisca Sepúlveda Lasseube Hortencia | E32: - | F32: Escuela Municipal Zuniga | G32: Francisca Hortencia Sepúlveda Lasseube | H32: 24925268-9 | J32: ="replace nombre = """&G32&""" if folio == """&A32&"""" -> replace nombre = "Francisca Hortencia Sepúlveda Lasseube" if folio == "23395A3" | K32: ="replace rut = """&H32&""" if folio == """&A32&"""" -> replace rut = "24925268-9" if folio == "23395A3"
A33: 23395A4 | B33: 5 | C33: A | D33: EZEQUIEL GUSTAVO MARTINEZ CAROCA | E33: - | F33: Escuela Municipal Zuniga | G33: Ezequiel Gustavo Martinez Caroca | H33: 24922618-1 | J33: ="replace nombre = """&G33&""" if folio == """&A33&"""" -> replace nombre = "Ezequiel Gustavo Martinez Caroca" if folio == "23395A4" | K33: ="replace rut = """&H33&""" if folio == """&A33&"""" -> replace rut = "24922618-1" if folio == "23395A4"
A34: 23395A5 | B34: 5 | C34: A | D34: Hernán Alonso Orellana Cañas | E34: - | F34: Escuela Municipal Zuniga | G34: Hernán Alonso Orellana Cañas | H34: 24832497-k | J34: ="replace nombre = """&G34&""" if folio == """&A34&"""" -> replace nombre = "Hernán Alonso Orellana Cañas" if folio == "23395A5" | K34: ="replace rut = """&H34&""" if folio == """&A34&"""" -> replace rut = "24832497-k" if folio == "23395A5"
A35: 23395A6 | B35: 5 | C35: A | D35: Rodolfo Sebastian Valenzuela Ibañez | E35: - | F35: Escuela Municipal Zuniga | G35: Rodolfo Sebastián Valenzuela Ibañez | H35: 24664469-1 | J35: ="replace nombre = """&G35&""" if folio == """&A35&"""" -> replace nombre = "Rodolfo Sebastián Valenzuela Ibañez" if folio == "23395A6" | K35: ="replace rut = """&H35&""" if folio == """&A35&"""" -> replace rut = "24664469-1" if folio == "23395A6"
A36: 24554A2 | B36: 4 | C36: A | D36: José Antonio Herrera Mansalves | E36: - | F36: Colegio Inmaculada Concepcion | G36: José Antonio Herrera Monsalves | H36: 25216263-1 | J36: ="replace nombre = """&G36&""" if folio == """&A36&"""" -> replace nombre = "José Antonio Herrera Monsalves" if folio == "24554A2" | K36: ="replace rut = """&H36&""" if folio == """&A36&"""" -> replace rut = "25216263-1" if folio == "24554A2"
A37: 24554B2 | B37: 4 | C37: B | D37: Alonso Enrique Arancibia Collana | E37: - | F37: Colegio Inmaculada Concepcion | G37: Alonso Enrique Orellana Aranibar | H37: 25133877-9 | J37: ="replace nombre = """&G37&""" if folio == """&A37&"""" -> replace nombre = "Alonso Enrique Orellana Aranibar " if folio == "24554B2" | K37: ="replace rut = """&H37&""" if folio == """&A37&"""" -> replace rut = "25133877-9" if folio == "24554B2"
A38: 24554B3 | B38: 4 | C38: B | D38: Santiago Sepulveda Areyuna Alamo | E38: - | F38: Colegio Inmaculada Concepcion | G38: Santiago Sepulveda Quezada Alonso | H38: 24950300-2 | J38: ="replace nombre = """&G38&""" if folio == """&A38&"""" -> replace nombre = "Santiago Sepulveda Quezada Alonso" if folio == "24554B3" | K38: ="replace rut = """&H38&""" if folio == """&A38&"""" -> replace rut = "24950300-2" if folio == "24554B3"
A39: 24555A1 | B39: 5 | C39: A | D39: Catalina Morales | E39: - | F39: Colegio Inmaculada Concepcion | G39: Catalina Morales | H39: 24817527-3 | J39: ="replace nombre = """&G39&""" if folio == """&A39&"""" -> replace nombre = "Catalina Morales " if folio == "24555A1" | K39: ="replace rut = """&H39&""" if folio == """&A39&"""" -> replace rut = "24817527-3" if folio == "24555A1"
... A83: 45304B2 | B83: 4 | C83: B | D83: Diego Alejandro Gisottana Yañez | E83: - | F83: Instituto San Sebastián Básico | G83: Diego Alejandro Crisostomo Yañez | H83: 25121078-0 | J83: ="replace nombre = """&G83&""" if folio == """&A83&"""" -> replace nombre = "Diego Alejandro Crisostomo Yañez" if folio == "45304B2" | K83: ="replace rut = """&H83&""" if folio == """&A83&"""" -> replace rut = "25121078-0" if folio == "45304B2"
A84: 45304B3 | B84: 4 | C84: B | D84: Amanda Doris, Marle Jara | E84: - | F84: Instituto San Sebastián Básico | G84: Amanda Doris MArre Jara | H84: 25005227-8 | J84: ="replace nombre = """&H84&""" if folio == """&A84&"""" -> replace nombre = "25005227-8" if folio == "45304B3" | K84: ="replace rut = """&#REF!&""" if folio == """&A84&"""" -> #REF!
A85: 45304B5 | B85: 4 | C85: B | D85: sofia contanza gomaler campos | E85: - | F85: Instituto San Sebastián Básico | G85: Sofía Constanza Gonzalez Campos | H85: 25046981-0 | J85: ="replace nombre = """&G85&""" if folio == """&A85&"""" -> replace nombre = "Sofía Constanza Gonzalez Campos" if folio == "45304B5" | K85: ="replace rut = """&H85&""" if folio == """&A85&"""" -> replace rut = "25046981-0" if folio == "45304B5"
A86: 45304B6 | B86: 4 | C86: B | D86: JADA MANUEL | E86: - | F86: Instituto San Sebastián Básico | G86: infante Gavilan Jorge Manuel | H86: 25320731-0 | J86: ="replace nombre = """&G86&""" if folio == """&A86&"""" -> replace nombre = "infante Gavilan Jorge Manuel" if folio == "45304B6" | K86: ="replace rut = """&H86&""" if folio == """&A86&"""" -> replace rut = "25320731-0" if folio == "45304B6"
A87: 45305A2 | B87: 5 | C87: A | D87: MONSERRAT PAREDES | E87: - | F87: Instituto San Sebastián Básico | G87: Paredes Ortega Monserrat del Carmen | H87: 24635808-7 | J87: ="replace nombre = """&G87&""" if folio == """&A87&"""" -> replace nombre = "Paredes Ortega Monserrat del Carmen" if folio == "45305A2" | K87: ="replace rut = """&H87&""" if folio == """&A87&"""" -> replace rut = "24635808-7" if folio == "45305A2"
A88: 45305A3 | B88: 5 | C88: A | D88: bayni millos salazar gonzalez | E88: - | F88: Instituto San Sebastián Básico | G88: Dafne Meliza Salazar Gonzalez | H88: 24927801-7 | J88: ="replace nombre = """&G88&""" if folio == """&A88&"""" -> replace nombre = "Dafne Meliza Salazar Gonzalez" if folio == "45305A3" | K88: ="replace rut = """&H88&""" if folio == """&A88&"""" -> replace rut = "24927801-7" if folio == "45305A3"
A89: 45305B2 | B89: 5 | C89: B | D89: leonor antonia vargas sanchez | E89: - | F89: Instituto San Sebastián Básico | G89: Leonor Antonia Vargas Sanchez | H89: 24820882-1 | J89: ="replace nombre = """&G89&""" if folio == """&A89&"""" -> replace nombre = "Leonor Antonia Vargas Sanchez" if folio == "45305B2" | K89: ="replace rut = """&H89&""" if folio == """&A89&"""" -> replace rut = "24820882-1" if folio == "45305B2"
A90: 45305B3 | B90: 5 | C90: B | D90: Yordan Alexis Escalon Rejalisto | E90: - | F90: Instituto San Sebastián Básico | G90: Yordan Alexis Escobar Rebolledo | H90: 24676129-9 | J90: ="replace nombre = """&G90&""" if folio == """&A90&"""" -> replace nombre = "Yordan Alexis Escobar Rebolledo" if folio == "45305B3" | K90: ="replace rut = """&H90&""" if folio == """&A90&"""" -> replace rut = "24676129-9" if folio == "45305B3"
...

Sheet rbds
A1: nom_est | B1: rbd | C1: region
A2: Andalien de Colina | B2: 10404 | C2: 13 | E2: ="replace nom_est = """&A2&""" if rbd == "&B2 -> replace nom_est = "Andalien de Colina" if rbd == 10404 | F2: ="replace region = "&C2&" if rbd == "&B2 -> replace region = 13 if rbd == 10404
A3: Centro Educación Evangélico De Hualpén | B3: 4782 | C3: 8 | E3: ="replace nom_est = """&A3&""" if rbd == "&B3 -> replace nom_est = "Centro Educación Evangélico De Hualpén" if rbd == 4782 | F3: ="replace region = "&C3&" if rbd == "&B3 -> replace region = 8 if rbd == 4782
A4: Colegio Alto del Maipo | B4: 31253 | C4: 13 | E4: ="replace nom_est = """&A4&""" if rbd == "&B4 -> replace nom_est = "Colegio Alto del Maipo" if rbd == 31253 | F4: ="replace region = "&C4&" if rbd == "&B4 -> replace region = 13 if rbd == 31253
A5: Colegio Colegio Martín Luther | B5: 4650 | C5: 8 | E5: ="replace nom_est = """&A5&""" if rbd == "&B5 -> replace nom_est = "Colegio Colegio Martín Luther" if rbd == 4650 | F5: ="replace region = "&C5&" if rbd == "&B5 -> replace region = 8 if rbd == 4650
A6: Colegio Inmaculada Concepcion | B6: 2455 | C6: 6 | E6: ="replace nom_est = """&A6&""" if rbd == "&B6 -> replace nom_est = "Colegio Inmaculada Concepcion" if rbd == 2455 | F6: ="replace region = "&C6&" if rbd == "&B6 -> replace region = 6 if rbd == 2455
A7: Colegio Instituto San Jose | B7: 5153 | C7: 8 | E7: ="replace nom_est = """&A7&""" if rbd == "&B7 -> replace nom_est = "Colegio Instituto San Jose" if rbd == 5153 | F7: ="replace region = "&C7&" if rbd == "&B7 -> replace region = 8 if rbd == 5153
A8: Colegio instituto San Luis de Curacaví | B8: 10851 | C8: 13 | E8: ="replace nom_est = """&A8&""" if rbd == "&B8 -> replace nom_est = "Colegio instituto San Luis de Curacaví" if rbd == 10851 | F8: ="replace region = "&C8&" if rbd == "&B8 -> replace region = 13 if rbd == 10851
A9: Colegio Luis Amigo | B9: 4868 | C9: 8 | E9: ="replace nom_est = """&A9&""" if rbd == "&B9 -> replace nom_est = "Colegio Luis Amigo" if rbd == 4868 | F9: ="replace region = "&C9&" if rbd == "&B9 -> replace region = 8 if rbd == 4868
A10: Colegio Particular Subv. Children School | B10: 15515 | C10: 6 | E10: ="replace nom_est = """&A10&""" if rbd == "&B10 -> replace nom_est = "Colegio Particular Subv. Children School" if rbd == 15515 | F10: ="replace region = "&C10&" if rbd == "&B10 -> replace region = 6 if rbd == 15515
A11: Colegio Particular Whipple School | B11: 2155 | C11: 6 | E11: ="replace nom_est = """&A11&""" if rbd == "&B11 -> replace nom_est = "Colegio Particular Whipple School" if rbd == 2155 | F11: ="replace region = "&C11&" if rbd == "&B11 -> replace region = 6 if rbd == 2155
A12: Colegio San José de Cabrero | B12: 4307 | C12: 8 | E12: ="replace nom_est = """&A12&""" if rbd == "&B12 -> replace nom_est = "Colegio San José de Cabrero" if rbd == 4307 | F12: ="replace region = "&C12&" if rbd == "&B12 -> replace region = 8 if rbd == 4307
A13: Colegio San Manuel | B13: 24675 | C13: 13 | E13: ="replace nom_est = """&A13&""" if rbd == "&B13 -> replace nom_est = "Colegio San Manuel" if rbd == 24675 | F13: ="replace region = "&C13&" if rbd == "&B13 -> replace region = 13 if rbd == 24675
... A43: Liceo Municipal f-n° 860 | B43: 10835 | C43: 13 | E43: ="replace nom_est = """&A43&""" if rbd == "&B43 -> replace nom_est = "Liceo Municipal f-n° 860" if rbd == 10835 | F43: ="replace region = "&C43&" if rbd == "&B43 -> replace region = 13 if rbd == 10835

Sheet 4_5_count
A1: school_grade | B1: rbd | C1: curso | D1: letra
A2: =B2&"-"&C2&"-"&D2 -> 2155-4-A | B2: 2155 | C2: 4 | D2: A
A3: =B3&"-"&C3&"-"&D3 -> 2155-4-A | B3: 2155 | C3: 4 | D3: A
A4: =B4&"-"&C4&"-"&D4 -> 2155-4-A | B4: 2155 | C4: 4 | D4: A
A5: =B5&"-"&C5&"-"&D5 -> 2155-4-A | B5: 2155 | C5: 4 | D5: A
A6: =B6&"-"&C6&"-"&D6 -> 2155-5-A | B6: 2155 | C6: 5 | D6: A
A7: =B7&"-"&C7&"-"&D7 -> 2155-5-A | B7: 2155 | C7: 5 | D7: A
A8: =B8&"-"&C8&"-"&D8 -> 2155-5-A | B8: 2155 | C8: 5 | D8: A
A9: =B9&"-"&C9&"-"&D9 -> 2155-5-A | B9: 2155 | C9: 5 | D9: A
A10: =B10&"-"&C10&"-"&D10 -> 2155-5-A | B10: 2155 | C10: 5 | D10: A
A11: =B11&"-"&C11&"-"&D11 -> 2155-5-A | B11: 2155 | C11: 5 | D11: A
A12: =B12&"-"&C12&"-"&D12 -> 2155-5-A | B12: 2155 | C12: 5 | D12: A
A13: =B13&"-"&C13&"-"&D13 -> 2155-4-A | B13: 2155 | C13: 4 | D13: A
... A4068: =B4068&"-"&C4068&"-"&D4068 -> 40038-5-B | B4068: 40038 | C4068: 5 | D4068: B

Sheet 6_7_count
A1: school_grade | B1: rbd | C1: curso | D1: letra
A2: =B2&"-"&C2&"-"&D2 -> 2155-6-A | B2: 2155 | C2: 6 | D2: A
A3: =B3&"-"&C3&"-"&D3 -> 2155-6-A | B3: 2155 | C3: 6 | D3: A
A4: =B4&"-"&C4&"-"&D4 -> 2155-6-A | B4: 2155 | C4: 6 | D4: A
A5: =B5&"-"&C5&"-"&D5 -> 2155-6-A | B5: 2155 | C5: 6 | D5: A
A6: =B6&"-"&C6&"-"&D6 -> 2155-6-A | B6: 2155 | C6: 6 | D6: A
A7: =B7&"-"&C7&"-"&D7 -> 2155-6-A | B7: 2155 | C7: 6 | D7: A
A8: =B8&"-"&C8&"-"&D8 -> 2155-6-A | B8: 2155 | C8: 6 | D8: A
A9: =B9&"-"&C9&"-"&D9 -> 2155-6-A | B9: 2155 | C9: 6 | D9: A
A10: =B10&"-"&C10&"-"&D10 -> 2155-6-A | B10: 2155 | C10: 6 | D10: A
A11: =B11&"-"&C11&"-"&D11 -> 2155-6-A | B11: 2155 | C11: 6 | D11: A
A12: =B12&"-"&C12&"-"&D12 -> 2155-6-A | B12: 2155 | C12: 6 | D12: A
A13: =B13&"-"&C13&"-"&D13 -> 2155-6-A | B13: 2155 | C13: 6 | D13: A
... A3017: =B3017&"-"&C3017&"-"&D3017 -> 10835-7-A | B3017: 10835 | C3017: 7 | D3017: A
A3018: =B3018&"-"&C3018&"-"&D3018 -> 10835--A | B3018: 10835 | D3018: A
A3019: =B3019&"-"&C3019&"-"&D3019 -> 10836-6-A | B3019: 10836 | C3019: 6 | D3019: A
A3020: =B3020&"-"&C3020&"-"&D3020 -> 10836-6-A | B3020: 10836 | C3020: 6 | D3020: A
A3021: =B3021&"-"&C3021&"-"&D3021 -> 10836-6-A | B3021: 10836 | C3021: 6 | D3021: A
A3022: =B3022&"-"&C3022&"-"&D3022 -> 10836-6-A | B3022: 10836 | C3022: 6 | D3022: A
A3023: =B3023&"-"&C3023&"-"&D3023 -> 10836-6-A | B3023: 10836 | C3023: 6 | D3023: A
A3024: =B3024&"-"&C3024&"-"&D3024 -> 10836-6-A | B3024: 10836 | C3024: 6 | D3024: A
A3025: =B3025&"-"&C3025&"-"&D3025 -> 10836-6-A | B3025: 10836 | C3025: 6 | D3025: A
A3026: =B3026&"-"&C3026&"-"&D3026 -> 10836-6-A | B3026: 10836 | C3026: 6 | D3026: A
A3027: =B3027&"-"&C3027&"-"&D3027 -> 10836-6-A | B3027: 10836 | C3027: 6 | D3027: A
A3028: =B3028&"-"&C3028&"-"&D3028 -> 10836-6-A | B3028: 10836 | C3028: 6 | D3028: A
A3029: =B3029&"-"&C3029&"-"&D3029 -> 10836-6-A | B3029: 10836 | C3029: 6 | D3029: A
A3030: =B3030&"-"&C3030&"-"&D3030 -> 10836-6-A | B3030: 10836 | C3030: 6 | D3030: A
... A3313: =B3313&"-"&C3313&"-"&D3313 -> 10851-7-A | B3313: 10851 | C3313: 7 | D3313: A
A3314: =B3314&"-"&C3314&"-"&D3314 -> 10851--A | B3314: 10851 | D3314: A
A3315: =B3315&"-"&C3315&"-"&D3315 -> 11248-6-A | B3315: 11248 | C3315: 6 | D3315: A
A3316: =B3316&"-"&C3316&"-"&D3316 -> 11248-6-A | B3316: 11248 | C3316: 6 | D3316: A
A3317: =B3317&"-"&C3317&"-"&D3317 -> 11248-6-A | B3317: 11248 | C3317: 6 | D3317: A
A3318: =B3318&"-"&C3318&"-"&D3318 -> 11248-6-A | B3318: 11248 | C3318: 6 | D3318: A
A3319: =B3319&"-"&C3319&"-"&D3319 -> 11248-6-A | B3319: 11248 | C3319: 6 | D3319: A
A3320: =B3320&"-"&C3320&"-"&D3320 -> 11248-6-A | B3320: 11248 | C3320: 6 | D3320: A
A3321: =B3321&"-"&C3321&"-"&D3321 -> 11248-6-A | B3321: 11248 | C3321: 6 | D3321: A
A3322: =B3322&"-"&C3322&"-"&D3322 -> 11248-6-A | B3322: 11248 | C3322: 6 | D3322: A
A3323: =B3323&"-"&C3323&"-"&D3323 -> 11248-6-A | B3323: 11248 | C3323: 6 | D3323: A
A3324: =B3324&"-"&C3324&"-"&D3324 -> 11248-6-A | B3324: 11248 | C3324: 6 | D3324: A
A3325: =B3325&"-"&C3325&"-"&D3325 -> 11248-6-A | B3325: 11248 | C3325: 6 | D3325: A
...

Sheet Encuesta CON Folios
A1: rbd | B1: region | C1: nom_est | D1: curso | E1: letra | F1: FOLIO
A2: 10404 | B2: 13 | C2: Andalien de Colina | D2: 4 | E2: A | F2: =concat(concat(A2,D2), E2) -> 104044A
A3: 10404 | B3: 13 | C3: Andalien de Colina | D3: 5 | E3: A | F3: =concat(concat(A3,D3), E3) -> 104045A
A4: 10404 | B4: 13 | C4: Andalien de Colina | D4: 5 | E4: B | F4: =concat(concat(A4,D4), E4) -> 104045B
A5: 10404 | B5: 13 | C5: Andalien de Colina | D5: 4 | E5: B | F5: =concat(concat(A5,D5), E5) -> 104044B
A6: 4782 | B6: 8 | C6: Centro Educación Evangélico De Hualpén | D6: 4 | E6: A | F6: =concat(concat(A6,D6), E6) -> 47824A
A7: 4782 | B7: 8 | C7: Centro Educación Evangélico De Hualpén | D7: 4 | E7: B | F7: =concat(concat(A7,D7), E7) -> 47824B
A8: 4782 | B8: 8 | C8: Centro Educación Evangélico De Hualpén | D8: 5 | E8: A | F8: =concat(concat(A8,D8), E8) -> 47825A
A9: 4782 | B9: 8 | C9: Centro Educación Evangélico De Hualpén | D9: 5 | E9: B | F9: =concat(concat(A9,D9), E9) -> 47825B
A10: 31253 | B10: 13 | C10: Colegio Alto del Maipo | D10: 4 | E10: A | F10: =concat(concat(A10,D10), E10) -> 312534A
A11: 31253 | B11: 13 | C11: Colegio Alto del Maipo | D11: 5 | E11: A | F11: =concat(concat(A11,D11), E11) -> 312535A
A12: 4650 | B12: 8 | C12: Colegio Colegio Martín Luther | D12: 4 | E12: A | F12: =concat(concat(A12,D12), E12) -> 46504A
A13: 4650 | B13: 8 | C13: Colegio Colegio Martín Luther | D13: 5 | E13: A | F13: =concat(concat(A13,D13), E13) -> 46505A
... A209: 10835 | B209: 13 | C209: Liceo Municipal f-n° 860 | D209: 6 | E209: A | F209: =concat(concat(A209,D209), E209) -> 108356A
C6229: ANDALIEN DE COLINA | D6229: 7 | E6229: a | F6229: 102064 | G6229: 102058 | H6229: 102036 | I6229: 102041 | J6229: 102056 | K6229: 102035 | L6229: 102065 | M6229: 102047
C6230: ANDALIEN DE COLINA | D6230: 7 | E6230: b | F6230: 102028
C6231: ANDALIEN DE COLINA | D6231: 6 | E6231: a | F6231: 102123
C6232: ANDALIEN DE COLINA | D6232: 6 | E6232: b | F6232: 102084 | G6232: 102076 | H6232: 102094
C6233: ANDALIEN DE COLINA | D6233: 5 | E6233: b | F6233: 101101 | G6233: 101080 | H6233: 101073 | I6233: 101081
C6234: ANDALIEN DE COLINA | D6234: 5 | E6234: a | F6234: 101049 | G6234: 101056 | H6234: 101035 | I6234: 101054
C6235: ANDALIEN DE COLINA | D6235: 4 | E6235: a | F6235: 101024 | G6235: 101016 | H6235: 101016 | I6235: 101010 | J6235: 101014 | K6235: 101017
C6236: ANDALIEN DE COLINA | D6236: 4 | E6236: b | F6236: 101124 | G6236: 101120 | H6236: 101113
C6237: ESCUELA BASICA SANTA MARTA DE LIRAY | D6237: 7 | E6237: a | F6237: 452089 | G6237: 452114
C6238: ESCUELA BASICA SANTA MARTA DE LIRAY | D6238: 6 | E6238: a | F6238: 542010 | G6238: 452003 | H6238: 452018 | I6238: 452002
C6239: ESCUELA BASICA SANTA MARTA DE LIRAY | D6239: 6 | E6239: b | F6239: 452064
C6240: ESCUELA BASICA SANTA MARTA DE LIRAY | D6240: 5 | E6240: a
C6241: ESCUELA BASICA SANTA MARTA DE LIRAY | D6241: 4 | E6241: a
C6242: Colegio San José de Cabrero | D6242: 7 | E6242: a | F6242: 262085
C6243: Colegio San José de Cabrero | D6243: 7 | E6243: b | F6243: 262130 | G6243: 262151
C6244: Colegio San José de Cabrero | D6244: 6 | E6244: a | F6244: 262031 | G6244: 262028 | H6244: 262013
C6245: Colegio San José de Cabrero | D6245: 6 | E6245: b
C6246: Colegio San José de Cabrero | D6246: 5 | E6246: a
C6247: Colegio San José de Cabrero | D6247: 5 | E6247: b | F6247: 261154
C6248: Colegio San José de Cabrero | D6248: 4 | E6248: a | F6248: 261034
C6249: Colegio San José de Cabrero | D6249: 4 | E6249: b | F6249: 261071
C6250: Centro Educación Evangélico De Hualpén | D6250: 7 | E6250: a | F6250: 122085 | G6250: 122069
C6251: Centro Educación Evangélico De Hualpén | D6251: 7 | E6251: b
C6252: Centro Educación Evangélico De Hualpén | D6252: 6 | E6252: a | F6252: 122012
C6253: Centro Educación Evangélico De Hualpén | D6253: 6 | E6253: b
C6254: Centro Educación Evangélico De Hualpén | D6254: 5 | E6254: a
...

Sheet Encuesta SIN folio
A1: nom_est | B1: curso | C1: letra | D1: NOMBRE
A2: ANDALIEN DE COLINA | B2: 7 | C2: a | D2: MAITTE VALENZUELA. ALEJANDRA CALDERÓN. DUHAN ARCE. VICTORIA ORTIZ
A3: ANDALIEN DE COLINA | B3: 7 | C3: b | D3: JOSÉ RUBIO. ROSARIO PALOMO. SOFIA GODOY. DIEGO GODOY. MIJAIL MORENO.
A4: ANDALIEN DE COLINA | B4: 6 | C4: a | D4: TOMAS LOPEZ. JEFERSON VIDAL.YSIDORA PEREZ. ANTONELLA PONCE. YESSICA ELGUITA.
A5: ANDALIEN DE COLINA | B5: 6 | C5: b | D5: SOLEDAD URRUTIA. JEMERY CONTRERAS. JULIO CASTILLO. KENDRO SANCHEZ. SINAHI NEGRETTE. NAYLA MANAMI.
A6: ANDALIEN DE COLINA | B6: 5 | C6: b | D6: FLORENCIA BEZZOLO. AYELEN MOYANO. SAMANTH RALDILINEZ. SCLALAMIT SALINAS. MARTIN CALDERÓN.
A7: ANDALIEN DE COLINA | B7: 5 | C7: a | D7: TOMÁS VOLEYUCLO. VALENTINA GONZALES. VALERIA SANDOVAL. AMANDA MENDEZ. ANAIS DURÁN. JOHAN HERNANDEZ. JUAN FERNANDEZ
A8: ANDALIEN DE COLINA | B8: 4 | C8: a | D8: RAYEN URRUTIA. MILEY MORAN. VILCHES AMARAY. XIOMARA PALACIOS
A9: ANDALIEN DE COLINA | B9: 4 | C9: b | D9: DANIEL RUBIO. CATALINA REYES. JAVIER MAMANI
A10: ESCUELA BASICA SANTA MARTA DE LIRAY | B10: 7 | C10: a | D10: CATALINA FUENTEALBA.
A11: ESCUELA BASICA SANTA MARTA DE LIRAY | B11: 6 | C11: a | D11: DOMINIQUE VERGARA. AGUSTINA MORALES. AGUSTINA GUASTAFIERRO. LORDIN GOUVERNEUR. SAUL PARAELA. FELIPE ARANEDA. MARIA SILVA
A12: ESCUELA BASICA SANTA MARTA DE LIRAY | B12: 6 | C12: b | D12: RAYEN HUARACÁN
A13: ESCUELA BASICA SANTA MARTA DE LIRAY | B13: 5 | C13: a | D13: LEONOR SANCHEZ (SC). ALEXDANDER PIÑA. BASTIÁN RETAMAL. BENJAMIN HERNANDEZ. ESTEFANIA ARIAS. NICOLÁS BÁEZ. GABRIEL ESNOLADO. CATALINA PASTÉN.
... A30: Centro Educación Evangélico De Hualpén | B30: 4 | C30: b | D30: GIANELLA ESPARZA. MIA BASCUÑAN. MAXIMILIANO VIDAL.PEDRO NEIRA. JAVIERA MUÑOZ. AMY SEPÚLVEDA. ZHIAREM FIGUEROA
A31: Liceo La Asuncion | B31: 7 | C31: a
A32: Liceo La Asuncion | B32: 7 | C32: b
A33: Liceo La Asuncion | B33: 7 | C33: c
A34: Liceo La Asuncion | B34: 7 | C34: d
A35: Liceo La Asuncion | B35: 7 | C35: e
A36: Liceo La Asuncion | B36: 6 | C36: a
A37: Liceo La Asuncion | B37: 6 | C37: b
A38: Liceo La Asuncion | B38: 6 | C38: c
A39: Liceo La Asuncion | B39: 6 | C39: d
A40: Liceo La Asuncion | B40: 6 | C40: e
A41: Liceo La Asuncion | B41: 5 | C41: a
A42: Liceo La Asuncion | B42: 5 | C42: b
... A45: Liceo La Asuncion | B45: 5 | C45: e
A46: Liceo La Asuncion | B46: 4 | C46: a | D46: FELIOE SUAZO. SOFIA RODRIGUEZ. ANARELLA PINTO. SOFIA GUTIERREZ. DYEHAN MUÑOZ. ENRIQUE ALVAREZ.
A47: Liceo La Asuncion | B47: 4 | C47: b | D47: BENJAMÍN RODRIGUEZ. THIAGO PINTO. VALENTINA MUÑOZ. MAXIMO CARRAZCO. JOSEFA CHÁVEZ. LEON MONTERO
A48: Liceo La Asuncion | B48: 4 | C48: c | D48: FACUNDO RIVERA. EMILIA PALMA. TRINIDAD SAN MARTÍN.
A49: Liceo La Asuncion | B49: 4 | C49: d | D49: EMILY ACEVEDO. PEDRO ROMERO. JOSEFA FAÚNDEZ. NOEMY LÓPEZ. ROCÍO HENRIQUEZ.
A50: Liceo La Asuncion | B50: 4 | C50: e | D50: JAVIER YEPSEN. MARTINA VILUGRÓN. JOSEFA RODRIGUEZ. MARTINA PINO. RENATO VASQUEZ. THOMÁS RIQUELME
A51: Escuela El Saber | B51: 7 | C51: a | D51: DARWIN GARCÉS. CRISTOBAL CID. MAXIMILIANO SALINAS.
A52: Escuela El Saber | B52: 7 | C52: b | D52: BENJAMÍN FIERRO.DANIEL VIVALLOS. MATÍAS NAVARRETE. AYNARA COLIHUINCA.
A53: Escuela El Saber | B53: 6 | C53: a | D53: VICENTE GÓMEZ. EMILIA CARRASCO
A54: Escuela El Saber | B54: 6 | C54: b | D54: DAMIÁN HIDALGO. YATNIEL NAVARRETE.NICLÁS MUÑOZ.
A55: Escuela El Saber | B55: 5 | C55: a | D55: MATIAS ELIOCU. MATEO CEA.
A56: Escuela El Saber | B56: 5 | C56: b | D56: ROMINA IBARRA.MATEO VENEGAS. EMILIA CIFUENTES. PEDRO DURAN
A57: Escuela El Saber | B57: 4 | C57: a | D57: CATALINA BOBARDILLA.
... A99: ESC.BASICA FRANCISCO PETRINOVIC KARLOVAC | B99: 5 | C99: a | D99: JHADIEL CHIRI. CONSUELO ESPINOZA. DIEGO ROJAS. NEHEMIAS AMESTICA.
...

Sheet SIN CONSENTIMIENTO
A1: nom_est | B1: curso | C1: letra | D1: FOLIO
A2: ANDALIEN DE COLINA | B2: 7 | C2: b | D2: 102022 | E2: 102018 | F2: 102003 | G2: 102006
A3: ESCUELA BASICA SANTA MARTA DE LIRAY | B3: 4 | C3: a | D3: 451017 | E3: SIN FOLIO (43) | F3: 451047 | G3: 451052
A4: Colegio San José de Cabrero | B4: 5 | C4: a | D4: 261086
A5: Colegio Inmaculada Concepcion | B5: 5 | C5: b | D5: 181094 | E5: 181098 | F5: 181148
A6: ESCUELA PREMIO NOBEL PABLO NERUDA | B6: 6 | C6: c | D6: 532081 | E6: 532072 | F6: 532069 | G6: 532083 | H6: 532064
A7: ESCUELA PREMIO NOBEL PABLO NERUDA | B7: 7 | C7: a | D7: 532111 | E7: 532103 | F7: 612
A8: Colegio Santa Claudia | B8: 5 | C8: a | D8: SIN FOLIO (673) | E8: SIN FOLIO (674)
A9: LICEO ESMERALDA | B9: 4 | C9: a | D9: 601005
A10: Colegio Particular Whipple School | B10: 7 | C10: b | D10: SIN FOLIO (746)
A11: ESCUELA BASICA SAN VICENTE DE LO ARCAYA | B11: 5 | C11: a | D11: 441045
A12: ESCUELA BASICA SAN VICENTE DE LO ARCAYA | B12: 7 | C12: a | D12: SIN FOLIO (829)
A13: LICEO MUNICIPAL F-N°860 | B13: 4 | C13: a | D13: 631056 | E13: 631049 | F13: 631031
A14: ESCUELA BASICA F-N°738 LOS RULOS | B14: 6 | C14: a | D14: 372028 | E14: 372043
A15: Escuela Básica Particular Paicavi de Lampa | B15: 6 | C15: a | D15: SIN FOLIO (923)
A16: Escuela Básica Particular Paicavi de Lampa | B16: 4 | C16: a | D16: SIN FOLIO (930)
A17: ESCUELA SAN FRANCISCO DE ASIS | B17: 5 | C17: a | D17: 541019
A18: ESCUELA BASICA G-N°737 SANTA EMILIA | B18: 4 | C18: a | D18: 401011
A19: Colegio San Manuel | B19: 6 | C19: a | D19: 272020
A20: ESCUELA BASICA MARCOS GOOYCOLEA CORTES | B20: 7 | C20: b | D20: 422098
A21: ESCUELA BASICA ALGARROBAL | B21: 6 | C21: a | D21: SIN FOLIO (1033)

Sheet CASO RARO
A1: FOLIO | D1: ESCUELA
A2: 261094 | B2: DATOS TACHADOS | D2: Colegio Whipple School Oriente | E2: Cursos completos sin folios, recomiendo revisar
A3: 261114 | B3: DATOS TACHADOS | E3: 4 | F3: a
A4: 562069 | B4: NO HAY PÁGINA INICIAL | E4: 4 | F4: b
A5: SIN FOLIO (784) | B5: NO HAY PÁGINA INICIAL | E5: 5 | F5: b
A6: SIN FOLIO (785) | B6: NO HAY PÁGINA INICIAL
A7: SIN FOLIO (786) | B7: NO HAY PÁGINA INICIAL
A8: 632051 | B8: SE RAYA TODA LA PÁGINA INICIAL Y RESPONDE TODO IGUAL
A9: SIN FOLIO (1007) | B9: NO SE ENTIENDE EL NOMBRE.
