Workbook

Sheet Hoja1
A1: folio | B1: rbd | C1: region | D1: nom_est | E1: curso | F1: letra | G1: Nombre final | H1: rut final | I1: dv | J1: Forma que toca linea intermedia | K1: Tipo | L1: Tipo de formulario | M1: Sexo | N1: folio_ | O1: sexo_
A2: 101001 | B2: 10404 | C2: 13 | D2: Andalien de Colina | E2: 4 | F2: A | G2: Flores Duarte Paz Valentina | H2: 25245963 | I2: 4 | J2: A | K2: Cont | L2: 4-5_A_Cont | M2: =LOOKUP(A2,N1:O8378,O1:O8378) -> Mujer | N2: 101004 | O2: Mujer
A3: 101002 | B3: 10404 | C3: 13 | D3: Andalien de Colina | E3: 4 | F3: A | G3: Rocha Rodriguez Adiek | H3: 25189710 | I3: 7 | J3: B | K3: Cont | L3: 4-5_B_Cont | M3: =LOOKUP(A3,N1:O8378,O1:O8378) -> Hombre | N3: 102002 | O3: Mujer
A4: 101003 | B4: 10404 | C4: 13 | D4: Andalien de Colina | E4: 4 | F4: A | G4: Giovani Williams | H4: 24828357 | I4: 2 | J4: B | K4: Cont | L4: 4-5_B_Cont | M4: =LOOKUP(A4,N1:O8378,O1:O8378) -> Hombre | N4: 102003 | O4: Hombre
A5: 101004 | B5: 10404 | C5: 13 | D5: Andalien de Colina | E5: 4 | F5: A | G5: Rivera Jimenez Anthonella Paz | H5: 25129418 | I5: 6 | J5: B | K5: Cont | L5: 4-5_B_Cont | M5: =LOOKUP(A5,N1:O8378,O1:O8378) -> Mujer | N5: 102004 | O5: Hombre
A6: 101005 | B6: 10404 | C6: 13 | D6: Andalien de Colina | E6: 4 | F6: A | G6: Muñoz Paredes Agustin Ignacio | H6: 24978837 | I6: 6 | J6: B | K6: Cont | L6: 4-5_B_Cont | M6: =LOOKUP(A6,N1:O8378,O1:O8378) -> Hombre | N6: 102005 | O6: Prefiero no decir
A7: 101006 | B7: 10404 | C7: 13 | D7: Andalien de Colina | E7: 4 | F7: A | G7: Hurtado Balladares Angia Alejandra | H7: 25229789 | I7: 8 | J7: B | K7: Cont | L7: 4-5_B_Cont | M7: =LOOKUP(A7,N1:O8378,O1:O8378) -> Mujer | N7: 102006 | O7: Hombre
A8: 101007 | B8: 10404 | C8: 13 | D8: Andalien de Colina | E8: 4 | F8: A | G8: Barria Sazo Analiz Esperanza | H8: 25223316 | I8: 4 | J8: B | K8: Cont | L8: 4-5_B_Cont | M8: =LOOKUP(A8,N1:O8378,O1:O8378) -> Mujer | N8: 102007 | O8: Prefiero no decir
A9: 101008 | B9: 10404 | C9: 13 | D9: Andalien de Colina | E9: 4 | F9: A | G9: Milla Restepo Dalis Alejandra | H9: 24732787 | I9: 8 | J9: A | K9: Cont | L9: 4-5_A_Cont | M9: =LOOKUP(A9,N1:O8378,O1:O8378) -> Mujer | N9: 102008 | O9: Mujer
A10: 101009 | B10: 10404 | C10: 13 | D10: Andalien de Colina | E10: 4 | F10: A | G10: Contreras Manzano Santino Leon | H10: 25243943 | I10: 9 | J10: A | K10: Cont | L10: 4-5_A_Cont | M10: =LOOKUP(A10,N1:O8378,O1:O8378) -> Hombre | N10: 102009 | O10: Mujer
A11: 101010 | B11: 10404 | C11: 13 | D11: Andalien de Colina | E11: 4 | F11: A | G11: Gonzalez Isabella Pascale | H11: 25117403 | I11: 8 | J11: A | K11: Cont | L11: 4-5_A_Cont | M11: =LOOKUP(A11,N1:O8378,O1:O8378) -> Mujer | N11: 102010 | O11: Mujer
A12: 101011 | B12: 10404 | C12: 13 | D12: Andalien de Colina | E12: 4 | F12: A | G12: Riquelme Torres Raul Tomas | H12: 25253746 | I12: 5 | J12: B | K12: Cont | L12: 4-5_B_Cont | M12: =LOOKUP(A12,N1:O8378,O1:O8378) -> Hombre | N12: 102011 | O12: Hombre
A13: 101012 | B13: 10404 | C13: 13 | D13: Andalien de Colina | E13: 4 | F13: A | G13: Molinna Lopez Eliseo Daniel | H13: 25216423 | I13: 5 | J13: B | K13: Cont | L13: 4-5_B_Cont | M13: =LOOKUP(A13,N1:O8378,O1:O8378) -> Hombre | N13: 102012 | O13: Mujer
A14: 101013 | B14: 10404 | C14: 13 | D14: Andalien de Colina | E14: 4 | F14: A | G14: Manriquez Sofia Marian | H14: 24980672 | I14: 2 | J14: A | K14: Cont | L14: 4-5_A_Cont | M14: =LOOKUP(A14,N1:O8378,O1:O8378) -> Mujer | N14: 102013 | O14: Hombre
A15: 101014 | B15: 10404 | C15: 13 | D15: Andalien de Colina | E15: 4 | F15: A | G15: Moran Muñoz Valentin Paz | H15: 25297520 | I15: 5 | J15: A | K15: Cont | L15: 4-5_A_Cont | M15: =LOOKUP(A15,N1:O8378,O1:O8378) -> Mujer | N15: 102014 | O15: Hombre
A16: 101015 | B16: 10404 | C16: 13 | D16: Andalien de Colina | E16: 4 | F16: A | G16: Oyace Airton | H16: 25252572 | I16: 6 | J16: B | K16: Cont | L16: 4-5_B_Cont | M16: =LOOKUP(A16,N1:O8378,O1:O8378) -> Hombre | N16: 102015 | O16: Hombre
A17: 101016 | B17: 10404 | C17: 13 | D17: Andalien de Colina | E17: 4 | F17: A | G17: Millalen Jara Josefa Antonia | H17: 25261202 | I17: 1 | J17: B | K17: Cont | L17: 4-5_B_Cont | M17: =LOOKUP(A17,N1:O8378,O1:O8378) -> Mujer | N17: 102016 | O17: Hombre
A18: 101017 | B18: 10404 | C18: 13 | D18: Andalien de Colina | E18: 4 | F18: A | G18: Morales Facundo | H18: 24172051 | I18: 7 | J18: A | K18: Cont | L18: 4-5_A_Cont | M18: =LOOKUP(A18,N1:O8378,O1:O8378) -> Hombre | N18: 102017 | O18: Mujer
A19: 101018 | B19: 10404 | C19: 13 | D19: Andalien de Colina | E19: 4 | F19: A | G19: Vargas Cancino Julieta Magdalena | H19: 25288649 | I19: 4 | J19: A | K19: Cont | L19: 4-5_A_Cont | M19: =LOOKUP(A19,N1:O8378,O1:O8378) -> Mujer | N19: 102018 | O19: Hombre
A20: 101019 | B20: 10404 | C20: 13 | D20: Andalien de Colina | E20: 4 | F20: A | G20: Salgado Nova Julian Ignacio | H20: 25256566 | I20: 3 | J20: A | K20: Cont | L20: 4-5_A_Cont | M20: =LOOKUP(A20,N1:O8378,O1:O8378) -> Hombre | N20: 102019 | O20: Mujer
A21: 101020 | B21: 10404 | C21: 13 | D21: Andalien de Colina | E21: 4 | F21: A | G21: Espinoza Hernandez Javier | H21: 25169495 | I21: 8 | J21: B | K21: Cont | L21: 4-5_B_Cont | M21: =LOOKUP(A21,N1:O8378,O1:O8378) -> Hombre | N21: 102020 | O21: Mujer
A22: 101021 | B22: 10404 | C22: 13 | D22: Andalien de Colina | E22: 4 | F22: A | G22: Quiroz Oyarzun Pascale Valentina | H22: 25217300 | I22: 5 | J22: A | K22: Cont | L22: 4-5_A_Cont | M22: =LOOKUP(A22,N1:O8378,O1:O8378) -> Mujer | N22: 102021 | O22: Mujer
A23: 101022 | B23: 10404 | C23: 13 | D23: Andalien de Colina | E23: 4 | F23: A | G23: Leon Lucas | H23: 27866177 | I23: 6 | J23: B | K23: Cont | L23: 4-5_B_Cont | M23: =LOOKUP(A23,N1:O8378,O1:O8378) -> Hombre | N23: 102022 | O23: Hombre
A24: 101023 | B24: 10404 | C24: 13 | D24: Andalien de Colina | E24: 4 | F24: A | G24: Medina Bueno Mariel Isidora | H24: 25241923 | I24: 3 | J24: B | K24: Cont | L24: 4-5_B_Cont | M24: =LOOKUP(A24,N1:O8378,O1:O8378) -> Mujer | N24: 102023 | O24: Hombre
A25: 101024 | B25: 10404 | C25: 13 | D25: Andalien de Colina | E25: 4 | F25: A | G25: Sepulveda Perez Yasmin Yanira | H25: 224553759 | I25: k | J25: B | K25: Cont | L25: 4-5_B_Cont | M25: =LOOKUP(A25,N1:O8378,O1:O8378) -> Mujer | N25: 102024 | O25: Hombre
A26: 101025 | B26: 10404 | C26: 13 | D26: Andalien de Colina | E26: 4 | F26: A | G26: Padilla Heider Rodrigo | H26: 25460737 | I26: 1 | J26: B | K26: Cont | L26: 4-5_B_Cont | M26: =LOOKUP(A26,N1:O8378,O1:O8378) -> Prefiero no decir | N26: 102025 | O26: Hombre
A27: 101026 | B27: 10404 | C27: 13 | D27: Andalien de Colina | E27: 4 | F27: A | G27: Navarro Espinoza Isabella | H27: 25080190 | I27: 4 | J27: A | K27: Cont | L27: 4-5_A_Cont | M27: =LOOKUP(A27,N1:O8378,O1:O8378) -> Prefiero no decir | N27: 102026 | O27: Hombre
A28: 101027 | B28: 10404 | C28: 13 | D28: Andalien de Colina | E28: 4 | F28: A | G28: Muñoz Altamirano Agustina Margarita | H28: 25200343 | I28: 6 | J28: A | K28: Cont | L28: 4-5_A_Cont | M28: =LOOKUP(A28,N1:O8378,O1:O8378) -> Mujer | N28: 102027 | O28: Hombre
A29: 101028 | B29: 10404 | C29: 13 | D29: Andalien de Colina | E29: 4 | F29: A | G29: Lovera Perez Tiffanny Isabella | H29: 100373455 | I29: 9 | J29: B | K29: Cont | L29: 4-5_B_Cont | M29: =LOOKUP(A29,N1:O8378,O1:O8378) -> Mujer | N29: 102028 | O29: Hombre
A30: 101029 | B30: 10404 | C30: 13 | D30: Andalien de Colina | E30: 4 | F30: A | G30: Payacan Millaleo Ailen | H30: 25247159 | I30: 6 | J30: A | K30: Cont | L30: 4-5_A_Cont | M30: =LOOKUP(A30,N1:O8378,O1:O8378) -> Mujer | N30: 102029 | O30: Prefiero no decir
A31: 101030 | B31: 10404 | C31: 13 | D31: Andalien de Colina | E31: 4 | F31: A | G31: Alvares Lobo Mayte Catalina | H31: 24987584 | I31: 8 | J31: B | K31: Cont | L31: 4-5_B_Cont | M31: =LOOKUP(A31,N1:O8378,O1:O8378) -> Mujer | N31: 102030 | O31: Hombre
A32: 101031 | B32: 10404 | C32: 13 | D32: Andalien de Colina | E32: 4 | F32: A | G32: Padilla Jeremy | H32: 25460733 | I32: 9 | J32: A | K32: Cont | L32: 4-5_A_Cont | M32: =LOOKUP(A32,N1:O8378,O1:O8378) -> Hombre | N32: 102031 | O32: Mujer
A33: 101032 | B33: 10404 | C33: 13 | D33: Andalien de Colina | E33: 4 | F33: A | G33: Duarte Alvez Thiago Samir | H33: 25028831 | I33: k | J33: A | K33: Cont | L33: 4-5_A_Cont | M33: =LOOKUP(A33,N1:O8378,O1:O8378) -> Hombre | N33: 102032 | O33: Hombre
A34: 101033 | B34: 10404 | C34: 13 | D34: Andalien de Colina | E34: 4 | F34: A | G34: Villeggas Milovan | H34: 25122688 | I34: 1 | J34: B | K34: Cont | L34: 4-5_B_Cont | M34: =LOOKUP(A34,N1:O8378,O1:O8378) -> Hombre | N34: 102033 | O34: Mujer
A35: 101034 | B35: 10404 | C35: 13 | D35: Andalien de Colina | E35: 5 | F35: A | G35: Gutierrez Martin Jesus | H35: 24239677 | I35: 4 | J35: A | K35: Cont | L35: 4-5_A_Cont | M35: =LOOKUP(A35,N1:O8378,O1:O8378) -> Hombre | N35: 102034 | O35: Mujer
A36: 101035 | B36: 10404 | C36: 13 | D36: Andalien de Colina | E36: 5 | F36: A | G36: Morales Villalobos Dana Isabela | H36: 100425530 | I36: 1 | J36: B | K36: Cont | L36: 4-5_B_Cont | M36: =LOOKUP(A36,N1:O8378,O1:O8378) -> Mujer | N36: 102035 | O36: Mujer
A37: 101036 | B37: 10404 | C37: 13 | D37: Andalien de Colina | E37: 5 | F37: A | G37: Jorquera Urzua Cristobal Alexander | H37: 24197598 | I37: 3 | J37: A | K37: Cont | L37: 4-5_A_Cont | M37: =LOOKUP(A37,N1:O8378,O1:O8378) -> Hombre | N37: 102036 | O37: Hombre
A38: 101037 | B38: 10404 | C38: 13 | D38: Andalien de Colina | E38: 5 | F38: A | G38: Sofia | H38: 24891175 | I38: 1 | J38: B | K38: Cont | L38: 4-5_B_Cont | M38: =LOOKUP(A38,N1:O8378,O1:O8378) -> Mujer | N38: 102037 | O38: Hombre
A39: 101038 | B39: 10404 | C39: 13 | D39: Andalien de Colina | E39: 5 | F39: A | G39: Tapia Pere Javier | H39: 24556555 | I39: 0 | J39: B | K39: Cont | L39: 4-5_B_Cont | M39: =LOOKUP(A39,N1:O8378,O1:O8378) -> Hombre | N39: 102038 | O39: Mujer
A40: 101039 | B40: 10404 | C40: 13 | D40: Andalien de Colina | E40: 5 | F40: A | G40: Melillan Jeanpaul | H40: 24907474 | I40: 8 | J40: B | K40: Cont | L40: 4-5_B_Cont | M40: =LOOKUP(A40,N1:O8378,O1:O8378) -> Hombre | N40: 102039 | O40: Mujer
...

Sheet Sheet 1
A1: Table 1
A2: folio | B2: sexo
A3: 101004 | B3: Mujer | C3: 101004 | D3: Mujer
A4: 102002 | B4: Mujer
A5: 102003 | B5: Hombre
A6: 102004 | B6: Hombre
A7: 102005 | B7: Prefiero no decir
A8: 102006 | B8: Hombre
A9: 102007 | B9: Prefiero no decir
A10: 102008 | B10: Mujer
A11: 102009 | B11: Mujer
A12: 102010 | B12: Mujer
A13: 102011 | B13: Hombre
A14: 102012 | B14: Mujer
A15: 102013 | B15: Hombre
... A8379: 631061 | B8379: Mujer

Sheet Tabla dinámica 1 - Tabla dinámi
A1: Tabla dinámica 1
A2: Forma que toca linea intermedia | B2: Forma que toca linea intermedia
A3: curso | B3: A | C3: B | D3: Grand Total
A4: 4 | B4: 1047 | C4: 1036 | D4: 2083
A5: 5 | B5: 1039 | C5: 1035 | D5: 2074
A6: 6 | B6: 1104 | C6: 1037 | D6: 2141
A7: 7 | B7: 1025 | C7: 1053 | D7: 2078
A8: Grand Total | B8: 4215 | C8: 4161 | D8: 8376

Sheet Tabla dinámica 1 - Table 1
E3: =GETPIVOTDATA("Count of folio",'Tabla dinámica 1 - Tabla dinámi'!A2,"Forma que toca linea intermedia","A","curso",4)*0.1 -> 104.7 | F3: =GETPIVOTDATA("Count of folio",'Tabla dinámica 1 - Tabla dinámi'!A2,"Forma que toca linea intermedia","A","curso",4)*0.1 -> 104.7
E4: =GETPIVOTDATA("Count of folio",'Tabla dinámica 1 - Tabla dinámi'!A2,"Forma que toca linea intermedia","A","curso",5)*0.1 -> 103.9 | F4: =GETPIVOTDATA("Count of folio",'Tabla dinámica 1 - Tabla dinámi'!A2,"Forma que toca linea intermedia","A","curso",5)*0.1 -> 103.9
E5: =GETPIVOTDATA("Count of folio",'Tabla dinámica 1 - Tabla dinámi'!A2,"Forma que toca linea intermedia","A","curso",6)*0.1 -> 110.4 | F5: =GETPIVOTDATA("Count of folio",'Tabla dinámica 1 - Tabla dinámi'!A2,"Forma que toca linea intermedia","A","curso",6)*0.1 -> 110.4
E6: =GETPIVOTDATA("Count of folio",'Tabla dinámica 1 - Tabla dinámi'!A2,"Forma que toca linea intermedia","A","curso",7)*0.1 -> 102.5 | F6: =GETPIVOTDATA("Count of folio",'Tabla dinámica 1 - Tabla dinámi'!A2,"Forma que toca linea intermedia","A","curso",7)*0.1 -> 102.5
D12: 4-5 A | E12: =SUM(E3:E4) -> 208.6
D13: 4-5 B | E13: =SUM(F3:F4) -> 208.6
D14: 6-7 A | E14: =SUM(E5:E6) -> 212.9
D15: 6-7 B | E15: =SUM(F5:F6) -> 212.9
